#VRML_SIM R2025a utf8

EXTERNPROTO "https://raw.githubusercontent.com/cyberbotics/webots/R2025a/projects/objects/backgrounds/protos/TexturedBackground.proto"
EXTERNPROTO "https://raw.githubusercontent.com/cyberbotics/webots/R2025a/projects/objects/backgrounds/protos/TexturedBackgroundLight.proto"
EXTERNPROTO "https://raw.githubusercontent.com/cyberbotics/webots/R2025a/projects/objects/floors/protos/RectangleArena.proto"
EXTERNPROTO "https://raw.githubusercontent.com/cyberbotics/webots/R2025a/projects/robots/k-team/khepera1/protos/Khepera1.proto"
EXTERNPROTO "https://raw.githubusercontent.com/cyberbotics/webots/R2025a/projects/objects/floors/protos/Floor.proto"

WorldInfo {
  info [
    "A Khepera robot equipped with a gripper"
  ]
  title "Khepera Gripper"
  CFM 0.001
  ERP 0.4
  basicTimeStep 10
  contactProperties [
    ContactProperties {
      material1 "gripper"
      material2 "stick"
      coulombFriction [
        10
      ]
    }
    ContactProperties {
      material1 "khepera"
      coulombFriction [
        0.1
      ]
    }
  ]
}
Viewpoint {
  orientation -0.2751955688184272 0.27619800890747775 0.9208594131452679 1.649537013153099
  position 0.10269972807481942 -2.2150144616094076 1.368456531044486
}
TexturedBackground {
}
TexturedBackgroundLight {
}
RectangleArena {
  translation 0 0 -2.26951e-18
  rotation 0 1 0 4.692820414042842e-06
  floorSize 1.5 1.5
}
DEF OverheadCamera Robot {
  translation 0.1 -0.1 1.9
  rotation 0 -1 0 -1.56
  children [
    Camera {
      rotation 1 0 0 -1.5708
      name "overhead_camera"
      fieldOfView 0.85
      width 1024
      height 1024
    }
  ]
  name "overhead_camera"
  controller "overhead_camera_controller"
  supervisor TRUE
}
Khepera1 {
  translation -0.2836587729299062 -0.5655700217163322 0.00010190065023294066
  rotation 0.035042462913529235 -0.06440995527681911 0.9973080684794404 0.9988140577288217
  name "khepera"
  controller "my_controller"
  supervisor TRUE
  extensionSlot [
    DEF LIFT_HINGE_JOINT HingeJoint {
      jointParameters HingeJointParameters {
        position 6.64885402899152e-08
        axis 0 1 0
        anchor -0.01 0 0.022
      }
      device [
        RotationalMotor {
          name "motor"
        }
      ]
      endPoint Solid {
        translation -0.01 0 0.022
        rotation 0.5773504489613392 -0.5773502928357691 -0.5773500657717047 2.094395129481873
        children [
          DEF RIGHT_GRIP SliderJoint {
            jointParameters JointParameters {
              position 0.029000000000765386
              axis 1 0 0
            }
            device [
              LinearMotor {
                name "right grip"
                maxVelocity 0.1
                maxPosition 0.029000000000765386
                maxForce 100
              }
            ]
            endPoint Solid {
              translation 0.029000000000765386 0 -0.048
              rotation 0 1 0 1.5708
              children [
                Shape {
                  appearance PBRAppearance {
                    baseColor 0.8 0.8 0.8
                    roughness 1
                    metalness 0
                  }
                  geometry IndexedFaceSet {
                    coord Coordinate {
                      point [
                        0 -0.004 0.004
                        0.03 -0.004 0.002
                        0.03 -0.004 0.0001
                        0 -0.004 0.0001
                        0 -0.004 0.004
                        0 0.004 0.004
                        0.03 0.004 0.002
                        0.03 0.004 0.0001
                        0 0.004 0.0001
                        0 0.004 0.004
                      ]
                    }
                    coordIndex [
                      4, 3, 2, 1, 0, -1, 5, 6, 7, 8, 9, -1, 0, 1, 6, 5, -1, 1, 2, 7, 6, -1, 2, 3, 8, 7, -1, 3, 4, 9, 8, -1
                    ]
                  }
                }
                DistanceSensor {
                  translation 0.015 0 0
                  rotation 0 1 0 1.5708
                  name "ds"
                  lookupTable [
                    0 0 0
                    0.05 1000 0
                  ]
                  type "infra-red"
                }
              ]
              name "right grip"
              contactMaterial "gripper"
              boundingObject Pose {
                translation 0.015 0 0.003
                children [
                  Box {
                    size 0.028 0.007 0.005
                  }
                ]
              }
              physics Physics {
                density 100
                centerOfMass [
                  0.01 0 0
                ]
              }
            }
          }
          DEF LEFT_GRIP SliderJoint {
            jointParameters JointParameters {
              position 0.02900000000091496
              axis -1 0 0
            }
            device [
              LinearMotor {
                name "left grip"
                maxVelocity 0.1
                maxPosition 0.02900000000091496
                maxForce 100
              }
            ]
            endPoint Solid {
              translation -0.02900000000091496 0 -0.048
              rotation 0 1 0 -1.5708
              children [
                Shape {
                  appearance PBRAppearance {
                    baseColor 0.8 0.8 0.8
                    roughness 1
                    metalness 0
                  }
                  geometry IndexedFaceSet {
                    coord Coordinate {
                      point [
                        0 -0.004 0.0001
                        -0.03 -0.004 0.0001
                        -0.03 -0.004 0.002
                        0 -0.004 0.004
                        0 -0.004 0.0001
                        0 0.004 0.0001
                        -0.03 0.004 0.0001
                        -0.03 0.004 0.002
                        0 0.004 0.004
                        0 0.004 0.0001
                      ]
                    }
                    coordIndex [
                      4, 3, 2, 1, 0, -1, 5, 6, 7, 8, 9, -1, 0, 1, 6, 5, -1, 1, 2, 7, 6, -1, 2, 3, 8, 7, -1, 3, 4, 9, 8, -1
                    ]
                  }
                }
              ]
              name "left grip"
              contactMaterial "gripper"
              boundingObject Pose {
                translation -0.015 0 0.003
                children [
                  Box {
                    size 0.028 0.007 0.005
                  }
                ]
              }
              physics Physics {
                density 100
                centerOfMass [
                  -0.01 0 0
                ]
              }
            }
          }
          Shape {
            appearance PBRAppearance {
              baseColor 0.8 0.8 0.8
              roughness 1
              metalness 0
            }
            geometry IndexedFaceSet {
              coord Coordinate {
                point [
                  0.035 -0.004 0.006
                  0.035 -0.004 -0.048
                  -0.035 -0.004 -0.048
                  -0.035 -0.004 0.006
                  -0.025 -0.004 0.006
                  -0.025 -0.004 -0.03
                  -0.016 -0.004 -0.04
                  0.016 -0.004 -0.04
                  0.025 -0.004 -0.03
                  0.025 -0.004 0.006
                  0.035 -0.004 0.006
                  0.035 0.004 0.006
                  0.035 0.004 -0.048
                  -0.035 0.004 -0.048
                  -0.035 0.004 0.006
                  -0.025 0.004 0.006
                  -0.025 0.004 -0.03
                  -0.016 0.004 -0.04
                  0.016 0.004 -0.04
                  0.025 0.004 -0.03
                  0.025 0.004 0.006
                  0.035 0.004 0.006
                ]
              }
              coordIndex [
                10, 9, 8, 7, 6, 5, 4, 3, 2, 1, 0, -1, 11, 12, 13, 14, 15, 16, 17, 18, 19, 20, 21, -1, 0, 1, 12, 11, -1, 1, 2, 13, 12, -1, 2, 3, 14, 13, -1, 3, 4, 15, 14, -1, 4, 5, 16, 15, -1, 5, 6, 17, 16, -1, 6, 7, 18, 17, -1, 7, 8, 19, 18, -1, 8, 9, 20, 19, -1, 9, 10, 21, 20, -1
              ]
            }
          }
        ]
        boundingObject Pose {
          translation 0 0 -0.021
          children [
            Box {
              size 0.068 0.008 0.052
            }
          ]
        }
        physics Physics {
          density 100
          centerOfMass [
            0 0 -0.02
          ]
        }
      }
    }
    DEF GRIPPER_BASE Pose {
      translation -0.01 0 0.023
      rotation 0.5773502691896258 -0.5773502691896258 -0.5773502691896258 2.094395
      children [
        Shape {
          appearance PBRAppearance {
            baseColor 0.8 0.8 0.8
            roughness 1
            metalness 0
          }
          geometry Box {
            size 0.05 0.01 0.01
          }
        }
      ]
    }
    Camera {
      translation -0.01 0 0.035
      rotation 1 0 0 0
      children [
        Shape {
          appearance PBRAppearance {
            baseColor 0.70632 0.70632 0.70632
            roughness 1
            metalness 0
          }
          geometry DEF CAMERA Box {
            size 0.03 0.02 0.03
          }
        }
      ]
      boundingObject DEF CAMERA Box {
        size 0.03 0.02 0.03
      }
      physics Physics {
        density -1
        mass 0.02
      }
    }
  ]
}

# Row 1 (y = -0.375)
Floor {
  translation -0.375 -0.375 0.0001
  size 0.23 0.23
  appearance PBRAppearance {
    baseColor 0.5 0.5 0.5
    roughness 0.5
    metalness 0
  }
}
Floor {
  translation -0.125 -0.375 0.0001
  name "floor(1)"
  size 0.23 0.23
  appearance PBRAppearance {
    roughness 0.5
    metalness 0
  }
}
Floor {
  translation 0.125 -0.375 0.0001
  name "floor(2)"
  size 0.23 0.23
  appearance PBRAppearance {
    baseColor 0.5 0.5 0.5
    roughness 0.5
    metalness 0
  }
}
Floor {
  translation 0.375 -0.375 0.0001
  name "floor(3)"
  size 0.23 0.23
  appearance PBRAppearance {
    roughness 0.5
    metalness 0
  }
}

# Row 2 (y = -0.125)
Floor {
  translation -0.375 -0.125 0.0001
  name "floor(4)"
  size 0.23 0.23
  appearance PBRAppearance {
    roughness 0.5
    metalness 0
  }
}
Floor {
  translation -0.125 -0.125 0.0001
  name "floor(5)"
  size 0.23 0.23
  appearance PBRAppearance {
    baseColor 0.5 0.5 0.5
    roughness 0.5
    metalness 0
  }
}
Floor {
  translation 0.125 -0.125 0.0001
  name "floor(6)"
  size 0.23 0.23
  appearance PBRAppearance {
    roughness 0.5
    metalness 0
  }
}
Floor {
  translation 0.375 -0.125 0.0001
  name "floor(7)"
  size 0.23 0.23
  appearance PBRAppearance {
    baseColor 0.5 0.5 0.5
    roughness 0.5
    metalness 0
  }
}

# Row 3 (y = 0.125)
Floor {
  translation -0.375 0.125 0.0001
  name "floor(8)"
  size 0.23 0.23
  appearance PBRAppearance {
    baseColor 0.5 0.5 0.5
    roughness 0.5
    metalness 0
  }
}
Floor {
  translation -0.125 0.125 0.0001
  name "floor(9)"
  size 0.23 0.23
  appearance PBRAppearance {
    roughness 0.5
    metalness 0
  }
}
Floor {
  translation 0.125 0.125 0.0001
  name "floor(10)"
  size 0.23 0.23
  appearance PBRAppearance {
    baseColor 0.5 0.5 0.5
    roughness 0.5
    metalness 0
  }
}
Floor {
  translation 0.375 0.125 0.0001
  name "floor(11)"
  size 0.23 0.23
  appearance PBRAppearance {
    roughness 0.5
    metalness 0
  }
}

# Row 4 (y = 0.375)
Floor {
  translation -0.375 0.375 0.0001
  name "floor(12)"
  size 0.23 0.23
  appearance PBRAppearance {
    roughness 0.5
    metalness 0
  }
}
Floor {
  translation -0.125 0.375 0.0001
  name "floor(13)"
  size 0.23 0.23
  appearance PBRAppearance {
    baseColor 0.5 0.5 0.5
    roughness 0.5
    metalness 0
  }
}
Floor {
  translation 0.125 0.375 0.0001
  name "floor(14)"
  size 0.23 0.23
  appearance PBRAppearance {
    roughness 0.5
    metalness 0
  }
}
Floor {
  translation 0.375 0.375 0.0001
  name "floor(15)"
  size 0.23 0.23
  appearance PBRAppearance {
    baseColor 0.5 0.5 0.5
    roughness 0.5
    metalness 0
  }
}